fun main(){
    try {  
        val a = IntArray(5)  
        a[5] = 10 / 0  
    } catch (e: ArithmeticException) {  
        println("arithmetic exception catch")  
    } catch (e: ArrayIndexOutOfBoundsException) {  
        println("array index outofbounds exception")  
    } catch (e: Exception) {  
        println("parent exception class")  
    }  
    println("code after try catch...")  
}